Workbook

Sheet SimGait
A1: State: | C1: Cost func. consists one onde, no constraint/punishment on mechanical unstability
A2: Name | B2: Speed | D2: foot height | E2: Req. Cost | F2: Act. Cost | G2: max u | H2: gait stability | I2: mech. Stabiity | L2: gait Type | M2: angle1 | N2: angle2 | O2: speed sign
B3: Single | C3: Multi | I3: Aft. Imp. | J3: Dur. Walk | K3: At Imp.
A4: Temp_SimGait_Loop_1 | C4: 1.23 | D4: 2.85 | E4: 34 | F4: 23 | G4: 300 | H4: yes | I4: n | J4: y | K4: n | L4: good | M4: 12.66 | N4: 4.52 | O4: ++---
A5: Temp_SimGait_Loop_2 | C5: 0.81 | D5: 3.87 | E5: 18 | F5: 10.35 | G5: 160 | H5: yes | I5: n | J5: y | K5: n | L5: good | M5: 13 | N5: 5.25 | O5: ++---
A6: Temp_SimGait_Loop_3 | C6: 1.5 | D6: 10.22 | E6: 149 | F6: 76 | G6: -400 | H6: yes | I6: n | J6: y | K6: n | L6: no | M6: 11.43 | N6: 11.64 | O6: ++--- | P6: hip goes up down/too bended knee
A7: Temp_SimGait_Loop_4 | C7: 1.93 | D7: 11.73 | E7: 923 | F7: 345 | G7: 500 | H7: yes | I7: n | J7: n | K7: n | M7: 11.68 | N7: 7.77 | O7: ++--- | P7: Marsh
A8: Temp_SimGait_Loop_5 | B8: 1.03 | C8: 1.95 | D8: 8.69 | E8: 240 | F8: 55 | G8: -350 | H8: yes | I8: n | J8: n | K8: y | L8: good | M8: 11.79 | N8: 9.22 | O8: -++--
A9: Temp_SimGait_Loop_6 | B9: 1.07 | C9: *** | D9: *** | E9: *** | F9: *** | G9: *** | H9: no | I9: *** | J9: *** | K9: *** | L9: *** | M9: *** | N9: *** | O9: ***
A10: Temp_SimGait_Loop_7 | B10: 1.03 | C10: 1.46 | D10: 8.23 | E10: 85 | F10: 21 | G10: -125 | H10: yes | I10: y | J10: y | K10: n | L10: good | M10: 11.6 | N10: 8.21 | O10: ++---
A11: Temp_SimGait_Loop_8 | B11: 1.15 | C11: 1.15 | D11: 23 | E11: 83 | F11: 45 | G11: -300 | H11: yes | I11: n | J11: y | K11: n | M11: 16.2 | N11: 22.6 | O11: +++--- | P11: dola dola/too high knee
A12: Temp_SimGait_Loop_9 | B12: 1.004 | C12: *** | D12: *** | E12: *** | F12: *** | G12: *** | H12: no | I12: *** | J12: *** | K12: *** | L12: *** | M12: 10 | N12: 22 | O12: --++- | P12: the same as above
A13: Temp_SimGait_Loop_10 | B13: 1.01 | C13: *** | D13: *** | E13: *** | F13: *** | G13: *** | H13: no | I13: *** | J13: *** | K13: *** | L13: ***
A14: Temp_SimGait_Loop_11 | B14: 1.09 | C14: *** | D14: *** | E14: *** | F14: *** | G14: *** | H14: no | I14: *** | J14: *** | K14: *** | L14: ***
A15: Temp_SimGait_Loop_12 | B15: 1.09 | C15: *** | D15: *** | E15: *** | F15: *** | G15: *** | H15: no | I15: *** | J15: *** | K15: *** | L15: *** | P15: too high knee
A16: Temp_SimGait_Loop_13 | B16: *** | C16: *** | D16: *** | E16: *** | F16: *** | G16: *** | H16: no | I16: *** | J16: *** | K16: *** | L16: *** | P16: too high knee
A17: Temp_SimGait_Loop_14 | B17: *** | C17: *** | D17: *** | E17: *** | F17: *** | G17: *** | H17: no | I17: *** | J17: *** | K17: *** | L17: *** | P17: too high knee
A18: Temp_SimGait_Loop_15 | B18: *** | C18: *** | D18: *** | E18: *** | F18: *** | G18: *** | H18: no | I18: *** | J18: *** | K18: *** | L18: *** | P18: too high knee
A19: Temp_SimGait_Loop_16 | B19: *** | C19: *** | D19: *** | E19: *** | F19: *** | G19: *** | H19: no | I19: *** | J19: *** | K19: *** | L19: *** | P19: too high knee/High joint speed
A20: Temp_SimGait_Loop_17 | B20: *** | C20: *** | D20: *** | E20: *** | F20: *** | G20: *** | H20: no | I20: *** | J20: *** | K20: *** | L20: *** | P20: too high knee/High joint speed
A21: Temp_SimGait_Loop_18 | B21: *** | C21: *** | D21: *** | E21: *** | F21: *** | G21: *** | H21: no | I21: *** | J21: *** | K21: *** | L21: *** | P21: foot crosses over torso!
A22: Temp_SimGait_Loop_19 | B22: 1.01 | C22: 1.53 | D22: 8.54 | E22: 218 | F22: 61 | G22: -225 | H22: yes | I22: n | J22: n | K22: y | L22: good | M22: 12 | N22: 12 | O22: ++---
A23: Temp_SimGait_Loop_20 | B23: 1.06 | C23: 1.38 | D23: 3.32 | E23: 81 | F23: 28 | G23: 225 | H23: yes | I23: n | J23: y | K23: y | L23: good | M23: 11.5 | N23: 4.7 | O23: ++---
A26: Temp_SimGait_Loop_rB=0_1 | B26: 1.022 | C26: 1.7 | D26: 12 | E26: 319 | F26: 188 | G26: 200 | H26: yes | I26: y | J26: n | K26: y | L26: good | M26: 11 | N26: 8 | O26: ++---
A27: Temp_SimGait_Loop_rB=0_2 | B27: 1.09 | C27: 2.22 | D27: 6 | E27: 524 | F27: 276 | G27: 500 | H27: yes | I27: n | J27: n | K27: n | M27: 11 | N27: 6 | O27: -++-- | P27: پا را جلو می‌اندازد و کل ربات پایین می‌اید.
A28: Temp_SimGait_Loop_rB=0_3 | B28: 1.11 | C28: *** | D28: *** | E28: *** | F28: *** | G28: *** | H28: no | I28: *** | J28: *** | K28: *** | L28: ***
A29: Temp_SimGait_Loop_rB=0_4 | B29: 1.02 | C29: 1.54 | D29: 3 | E29: 96 | F29: 51-->(44) | G29: -200 | H29: yes | I29: y | J29: y | K29: y | L29: good | M29: 11 | N29: 4.7 | O29: +++--
A30: Temp_SimGait_Loop_rB=0_5 | B30: 0.99 | C30: 1.53 | D30: 4.7 | E30: 125 | F30: 70-->(54) | G30: 125 | H30: yes | I30: y | J30: y | K30: y | L30: good | M30: 11.9 | N30: 8.6 | O30: -+--- | P30: پا را جلو می‌اندازد و کل ربات پایین می‌اید.
A31: Temp_SimGait_Loop_rB=0_6 | B31: 1.07 | C31: *** | D31: *** | E31: *** | F31: *** | G31: *** | H31: no | I31: *** | J31: *** | K31: *** | L31: ***
A32: Temp_SimGait_Loop_rB=0_7 | B32: 1.06 | C32: *** | D32: *** | E32: *** | F32: *** | G32: *** | H32: no | I32: *** | J32: *** | K32: *** | L32: ***
A33: Temp_SimGait_Loop_rB=0_8 | B33: 1.15 | C33: 2.05 | D33: 3.4 | E33: 192 | F33: 96-->(84) | G33: 150 | H33: yes | I33: y | J33: y | K33: n | M33: 11.5 | N33: 6 | O33: ++--- | P33: کمر کمی زیاد جلو خم هست
A34: Temp_SimGait_Loop_rB=0_9 | B34: 1.02 | C34: 1.22 | D34: 1.66 | E34: 29 | F34: 20-->(16) | G34: -80 | H34: yes | I34: y | J34: y | K34: n | L34: good | M34: 11.6 | N34: 5.9 | O34: ++---
A35: Temp_SimGait_Loop_rB=0_10 | B35: 1.01 | C35: 1.17 | D35: 3.41 | E35: 27 | F35: 20--(16) | G35: 150 | H35: yes | I35: y | J35: y | K35: n | L35: good | M35: 11.3 | N35: 9 | O35: -++--
A36: Temp_SimGait_Loop_rB=0_11 | B36: 0.01 | C36: *** | D36: *** | E36: *** | F36: *** | G36: *** | I36: *** | J36: *** | K36: *** | L36: *** | P36: un-natraul motion
A37: Temp_SimGait_Loop_rB=0_12 | B37: 0.99 | C37: 2 | D37: 37 | E37: 1292 | F37: 813 | G37: -900 | H37: no | I37: n | J37: n | K37: y | M37: 9 | N37: 21 | O37: ++--- | P37: too high knee/Fn become negative
A38: Temp_SimGait_Loop_rB=0_13 | B38: 0.99 | C38: 1.5 | D38: 10.2 | E38: 223 | F38: 121-->(80) | G38: 200 | H38: yes | I38: n | J38: y | K38: n | L38: good | M38: 10.38 | N38: 5.2 | O38: +++--
A39: Temp_SimGait_Loop_rB=0_14 | B39: 0.99 | C39: 1.5 | D39: 8 | E39: 131 | F39: 100-->(76) | G39: -300 | H39: yes | I39: n | J39: y | K39: y | L39: good | M39: 11.5 | N39: 2.6 | O39: ++---
A40: Temp_SimGait_Loop_rB=0_15 | B40: 1.13 | C40: 1.08 | D40: 3.4 | E40: 27 | F40: 20-->(16) | G40: 150 | H40: yes | I40: y | J40: y | K40: n | L40: good | M40: 10.7 | N40: 5.03 | O40: +++--
A41: Temp_SimGait_Loop_rB=0_16
A42: Temp_SimGait_Loop_rB=0_17
...

Sheet Gait
A1: State: | C1: Cost func. consists 10 step, full constraint/punishment on mechanical unstability
A2: Name | B2: speed | D2: foot height | E2: Req. Work | F2: Act. Work | J2: max u | L2: gait stability | M2: mech. Stabiity | P2: gait Type | Q2: angle1 | R2: angle2 | S2: speed sign | T2: delta
B3: 1 Steps | C3: 10 Steps | F3: M | G3: MB | H3: MD | I3: MBD | J3: Req. | K3: Act (MB) | M3: Aft. Imp. | N3: Dur. Walk | O3: At Imp.
A4: TempMultiOde_Gait_1 | C4: 1.22 | D4: 8.68 | E4: 69 | G4: 28 | J4: 129 | K4: 156 | L4: y | M4: y | N4: y | O4: y | P4: good | Q4: 11.1 | R4: 4.7 | S4: -++--
A5: TempMultiOde_Gait_2 | B5: 0.86 | C5: 1.11 | D5: 10 | E5: 92 | G5: 52 | J5: 182 | K5: 137 | L5: y | M5: y | N5: y | O5: y | P5: Bala payyen | Q5: 12.7 | R5: 20.6 | S5: ++---
A6: TempMultiOde_Gait_3 | B6: 1.12 | C6: 0.84 | D6: 4.8 | E6: 23 | G6: 11 | J6: 43 | K6: 61 | L6: y | M6: y | N6: y | O6: y | P6: good | Q6: 12.3 | R6: 5.3
A7: TempMultiOde_Gait_4 | B7: 1.12 | C7: 0.89 | D7: 7.98 | E7: 34 | G7: 18 | J7: 51 | K7: 39 | L7: y | M7: y | N7: y | O7: y | P7: g | Q7: 12.3 | R7: 5.3 | S7: +++--
A8: TempMultiOde_Gait_5 | B8: 0.72 | C8: 1.19 | D8: 16.1 | E8: 126 | G8: 71 | J8: 187 | K8: 192 | L8: y | M8: n | N8: y | O8: y | P8: pa bala | Q8: 12.3 | R8: 8.8 | S8: -++--
A9: TempMultiOde_Gait_6 | B9: 1.21 | C9: 0.81 | D9: 9.6 | E9: 41 | G9: 29 | J9: 82 | K9: 63 | L9: y | M9: y | N9: y | O9: y | P9: good | Q9: 12.3 | R9: 5.9
A10: TempMultiOde_Gait_7 | B10: 0.96 | C10: 1.03 | D10: 3.2 | E10: 24 | G10: 16 | J10: 61 | K10: 43 | L10: y | M10: y | N10: y | O10: y | P10: roy zamin mikeshad | Q10: 12.6 | R10: 8.3 | S10: ++---
A11: TempMultiOde_Gait_8 | B11: 0.79 | C11: 1.09 | D11: 3.33 | E11: 19 | F11: 13.9 | G11: 12.53 | H11: 13.44 | I11: 12.44 | J11: 63 | K11: 73 | L11: y | M11: y | N11: y | O11: y | P11: roy zamin mikeshad | Q11: 12.4 | R11: 5.7 | S11: ++--- | T11: 0.8521
A12: TempMultiOde_Gait_9 | B12: 0.87 | C12: 1.07 | D12: 7 | E12: 33 | G12: 9.2 | J12: 88 | K12: 105 | L12: y | M12: y | N12: y | O12: y | P12: good | Q12: 12.4 | R12: 4.9
A13: TempMultiOde_Gait_10 | B13: 0.78 | C13: 1.09 | D13: 4.23 | E13: 35 | G13: 11 | J13: 85 | K13: 110 | L13: y | M13: y | N13: y | O13: y | P13: zano bala(kami) | Q13: 12.4 | R13: 6.2 | S13: -++--
A14: TempMultiOde_Gait_11 | B14: 0.7 | C14: 1.13 | D14: 3.4 | E14: 30 | G14: 16 | J14: 83 | K14: 61 | L14: y | M14: y | N14: y | O14: y | P14: good | Q14: 11.6 | R14: 5.2 | S14: +++--
A15: TempMultiOde_Gait_12 | B15: 1.4 | C15: 0.005 | D15: 4.49 | E15: -- | F15: -- | G15: -- | H15: -- | I15: -- | J15: -- | K15: -- | L15: n | M15: -- | N15: -- | O15: -- | P15: bad | S15: --++-
A16: TempMultiOde_Gait_13 | B16: 0.69 | C16: 1.14 | D16: 5.7 | E16: 40 | G16: 9 | J16: 99 | K16: 93 | L16: y | M16: y | N16: y | O16: y | P16: good | Q16: 10.8 | R16: 6.3 | S16: -++--
A17: TempMultiOde_Gait_14 | B17: 1.14 | C17: 0.92 | D17: 8.4 | E17: 38 | G17: 15 | J17: 78 | K17: 43 | L17: y | M17: y | N17: y | O17: y | P17: zano bala(kami) | Q17: 12.1 | R17: 5.7 | S17: +++--
A18: TempMultiOde_Gait_15 | B18: 0.55 | C18: 1.11 | D18: 3.6 | E18: 41 | G18: 13 | J18: 78 | K18: 107 | L18: y | M18: y | N18: y | O18: y | P18: good | Q18: 13.1 | R18: 6.11 | S18: -++--
A19: TempMultiOde_Gait_16 | B19: 1.03 | C19: 0.98 | D19: 10.39 | E19: 44 | G19: 19 | J19: 50 | K19: 35 | L19: y | M19: y | N19: y | O19: y | P19: zano bala(kami) | Q19: 12.6 | R19: 5 | S19: -++--
A20: TempMultiOde_Gait_17 | B20: 0.39 | C20: 1.29 | D20: 12.2 | E20: 96 | G20: 33 | J20: 77 | K20: 123 | P20: zano bala | Q20: 11.7 | R20: 5.7 | S20: +++--
A21: TempMultiOde_Gait_18 | B21: 1.13 | C21: 1.16 | D21: 9.24 | E21: 47 | G21: 14 | J21: 72 | K21: 51 | L21: y | M21: y | N21: y | O21: y | P21: zano bala(kami) | Q21: 12.3 | R21: 5.7 | S21: ++---
A22: TempMultiOde_Gait_19 | B22: 0.59 | C22: 1.16 | D22: 6.9 | E22: 48 | G22: 18 | J22: 63 | K22: 83 | L22: y | M22: y | N22: y | O22: y | P22: good | Q22: 13.1 | R22: 6.2 | S22: +++--
A23: TempMultiOde_Gait_20 | B23: 0.95 | C23: 1.06 | D23: 4.69 | E23: 31 | G23: 18 | J23: 140 | K23: 153 | L23: y | M23: y | N23: y | O23: y | P23: zano ziad kham misheh | Q23: 13.25 | R23: 14.37 | S23: ++---
D25: min | E25: =MIN(E4:E23) -> 19
A30: =A11 -> TempMultiOde_Gait_8 | B30: =B11 -> 0.79 | C30: =C11 -> 1.09 | D30: =D11 -> 3.33 | E30: =E11 -> 19 | F30: =F11 -> 13.9 | G30: =G11 -> 12.53 | H30: =H11 -> 13.44 | ... T30: =T11 -> 0.8521

Sheet SimGait_M
A1: State: | C1: Cost func. consists 10 step, full constraint/punishment on mechanical unstability
A2: Name | B2: speed | D2: foot height | E2: Req. Work | F2: Act. Work | J2: max u | L2: gait stability | M2: mech. Stabiity | P2: gait Type | Q2: angle1 | R2: angle2 | S2: speed sign | T2: delta
B3: 1 Steps | C3: 10 Steps | F3: M | G3: MB | H3: MD | I3: MBD | J3: Req. | K3: Act (MB) | M3: Aft. Imp. | N3: Dur. Walk | O3: At Imp.
A4: TempMultiOde_SimGait_M_1 | B4: 0.98 | C4: 1.13 | D4: 7.1 | E4: 45 | F4: 28 | J4: 65 | K4: 80 | L4: y | M4: y | N4: y | O4: y | P4: zano kham | Q4: 14.2 | R4: 16.08 | S4: ++---
A5: TempMultiOde_SimGait_M_2 | B5: ---- | C5: ---- | D5: ---- | E5: ---- | F5: ---- | G5: ---- | H5: ---- | I5: ---- | J5: ---- | K5: ---- | L5: n | M5: ---- | N5: ---- | O5: ----
A6: TempMultiOde_SimGait_M_3 | B6: 1.77 | C6: 0.5 | D6: 4.13 | E6: 18 | F6: 15 | J6: 61 | K6: 53 | L6: y | M6: y | N6: y | O6: y | P6: ro be kond | Q6: 14.8 | R6: 9.5 | S6: -+---
A7: TempMultiOde_SimGait_M_4 | B7: 0.66 | C7: 1.17 | D7: 10.56 | E7: 58 | F7: 46 | J7: 128 | K7: 147 | L7: y | M7: y | N7: y | O7: y | P7: kami zano bala | Q7: 14.3 | R7: 13.6 | S7: ++---
A8: TempMultiOde_SimGait_M_5 | B8: ---- | C8: ---- | D8: ---- | E8: ---- | F8: ---- | G8: ---- | H8: ---- | I8: ---- | J8: ---- | K8: ---- | L8: n | M8: ---- | N8: ---- | O8: ----
A9: TempMultiOde_SimGait_M_6 | B9: 0.53 | C9: 1.29 | D9: 21 | E9: 107 | F9: 79 | J9: 85 | K9: 105 | L9: y | M9: y | N9: y | O9: y | P9: kheili zano bala | Q9: 14.4 | R9: 11.4 | S9: ++---
A10: TempMultiOde_SimGait_M_7 | B10: 0.63 | C10: 1.08 | D10: 4.5 | E10: 30 | F10: 21 | J10: 73 | K10: 73 | L10: y | M10: y | N10: y | O10: y | P10: good | Q10: 14.2 | R10: 12.5 | S10: ++---
A11: TempMultiOde_SimGait_M_8 | B11: 1.3 | C11: 0.96 | D11: 4.6 | E11: 30 | F11: 18 | J11: 74 | K11: 38 | L11: y | M11: y | N11: y | O11: y | P11: zano saf nemishavad | Q11: 15.5 | R11: 13.33 | S11: ++---
A12: TempMultiOde_SimGait_M_9 | B12: 1.4 | C12: 1.07 | D12: 6.5 | E12: 40 | F12: 33 | J12: 70 | K12: 80 | L12: y | M12: y | N12: y | O12: y | P12: good | Q12: 15 | R12: 13.5 | S12: ++---
A13: TempMultiOde_SimGait_M_10 | B13: 1.1 | C13: 0.99 | D13: 12 | E13: 50 | F13: 39 | J13: 69 | K13: 83 | L13: y | M13: y | N13: y | O13: y | P13: kamar be jelo | Q13: 15 | R13: 13.9 | S13: ++---
A14: TempMultiOde_SimGait_M_11 | B14: 1.04 | C14: 1.02 | D14: 9.5 | E14: 44 | F14: 32 | J14: 75 | K14: 83 | L14: y | M14: y | N14: y | O14: y | P14: good | Q14: 14 | R14: 13.5 | S14: ++---
A15: TempMultiOde_SimGait_M_12 | B15: 0.96 | C15: 1.01 | D15: 6.2 | E15: 27.52 | F15: 20.49 | G15: 13.92 | H15: 18.77 | I15: 19.37 | J15: 39 | K15: 41 | L15: y | M15: y | N15: y | O15: y | P15: good | Q15: 14.11 | R15: 9.8 | S15: ++--- | T15: 0.785
A16: TempMultiOde_SimGait_M_13 | B16: ---- | C16: ---- | D16: ---- | E16: ---- | F16: ---- | G16: ---- | H16: ---- | I16: ---- | J16: ---- | K16: ---- | L16: n | M16: ---- | N16: ---- | O16: ---- | S16: ++---
A17: TempMultiOde_SimGait_M_14 | B17: 1.39 | C17: 0.72 | D17: 10.2 | E17: 38 | F17: 28 | J17: 87 | K17: 87 | L17: y | M17: y | N17: y | O17: y | P17: zani bala | Q17: 13.7 | R17: 3.12 | S17: -++--
A18: TempMultiOde_SimGait_M_15 | B18: 1.3 | C18: 0.88 | D18: 4.8 | E18: 24 | F18: 18 | J18: 39 | K18: 48 | L18: y | M18: y | N18: y | O18: y | P18: kamar ziad bazi dare | Q18: 15.37 | R18: 13.74 | S18: ++---
A19: TempMultiOde_SimGait_M_16 | B19: 1.4 | C19: 0.9 | D19: 5.8 | E19: 38 | F19: 27 | J19: 75 | K19: 92 | L19: y | M19: y | N19: y | O19: y | P19: harekat pa be aghab | Q19: 14.8 | R19: 13.3 | S19: ++---
A20: TempMultiOde_SimGait_M_17 | B20: ---- | C20: ---- | D20: ---- | E20: ---- | F20: ---- | G20: ---- | H20: ---- | I20: ---- | J20: ---- | K20: ---- | L20: n | M20: ---- | N20: ---- | O20: ----
A21: TempMultiOde_SimGait_M_18 | B21: 1.25 | C21: 0.92 | D21: 3.9 | E21: 30.2 | F21: 20.9 | J21: 66 | K21: 79 | L21: y | M21: y | N21: y | O21: y | P21: good | Q21: 15.2 | R21: 12.9 | S21: ++---
A22: TempMultiOde_SimGait_M_19 | B22: 1.5 | C22: 0.81 | D22: 5.5 | E22: 35 | F22: 29 | J22: 108 | K22: 110 | L22: y | M22: y | N22: y | O22: y | P22: good | Q22: 14.8 | R22: 13.1 | S22: ++---
A23: TempMultiOde_SimGait_M_20 | B23: 1.4 | C23: 0.59 | D23: 3.2 | E23: 18 | F23: 12 | J23: 41 | K23: 38 | L23: y | M23: y | N23: y | O23: y | P23: good | Q23: 14.1 | R23: 8.7 | S23: ++---
A24: 21 | B24: 0.74 | C24: 1.11 | D24: 2.5 | E24: 44 | F24: 32 | J24: 82 | K24: 80 | L24: y | M24: y | N24: y | O24: y | P24: kamarkami bzai darad | Q24: 12.2 | R24: 5.4 | S24: ++---
A25: 22 | C25: 0.89 | D25: 5.1 | E25: 52 | F25: 46 | J25: 93 | K25: 92 | L25: y | M25: y | N25: y | O25: y | P25: kami zano bala | Q25: 12.09 | R25: 6.3 | S25: -++--
A26: 23 | B26: 1.16 | L26: n
A27: 24 | C27: 1.01 | D27: 2.7 | E27: 23 | F27: 20 | J27: 65 | K27: 31 | L27: y | M27: y | N27: y | O27: y | P27: good | Q27: 13.5 | R27: 4.5 | S27: +++--
A28: 25 | C28: 1.09 | D28: 4.9 | E28: 37 | F28: 36 | J28: 57 | K28: 49 | L28: y | M28: y | N28: y | O28: y | P28: good | Q28: 12.7 | R28: 7.8 | S28: +++--
A29: 26 | C29: 1.19 | D29: 14 | E29: 129 | F29: 103 | J29: 92 | K29: 69 | L29: y | M29: y | N29: y | O29: y | P29: zano bloand | Q29: 11.8 | R29: 7 | S29: +++--
A30: 27 | C30: 1.04 | D30: 4 | E30: 31 | F30: 27 | J30: 67 | K30: 80 | L30: y | M30: y | N30: y | O30: y | P30: good | Q30: 12.9 | R30: 6.9 | S30: +++--
A31: 28 | B31: 0.89 | C31: 1.19 | D31: 1.88 | E31: 26 | F31: 12.74 | G31: 7.65 | H31: 11.59 | I31: 8.86 | J31: 53 | K31: 66 | L31: y | M31: y | N31: y | O31: y | P31: good | Q31: 12.2 | R31: 3.7 | S31: ++--- | T31: 0.899
A32: 29 | L32: n | S32: ++
A33: 30 | B33: 0.95 | C33: 1.08 | D33: 14 | E33: 115 | F33: 90 | J33: 181 | K33: 181 | L33: y | M33: y | N33: y | O33: y | P33: pa aghab | Q33: 10.3 | R33: 6.8 | S33: +++-
A35: =A15 -> TempMultiOde_SimGait_M_12 | B35: =B15 -> 0.96 | C35: =C15 -> 1.01 | D35: =D15 -> 6.2 | E35: =E15 -> 27.52 | F35: =F15 -> 20.49 | G35: =G15 -> 13.92 | H35: =H15 -> 18.77 | ... T35: =T15 -> 0.785

Sheet SimGait_MB
A1: State: | C1: Cost func. consists one 10 step, full constraint/punishment on mechanical unstability
A2: Name | B2: speed | D2: foot height | E2: Req. Work | F2: Act. Work | J2: max u | L2: gait stability | M2: mech. Stabiity | P2: gait Type | Q2: angle1 | R2: angle2 | S2: speed sign | T2: delta
B3: 1 Steps | C3: 10 Steps | F3: M | G3: MB | H3: MD | I3: MBD | J3: Req. | K3: Act (MB) | M3: Aft. Imp. | N3: Dur. Walk | O3: At Imp.
A4: TempMultiOde_SimGait_MB_1 | B4: 2.17 | C4: 2.78 | D4: 12.9 | E4: 515 | G4: 171 | J4: 405 | K4: 216 | L4: y | M4: n | N4: n | O4: y | P4: zano boland | Q4: 11.8 | R4: 6.7 | S4: ++-+-
A5: TempMultiOde_SimGait_MB_2 | B5: 0.58 | C5: 1.25 | D5: 6.9 | E5: 55 | G5: 9.8 | J5: 80 | K5: 48 | L5: y | M5: y | N5: y | O5: y | P5: good | Q5: 10.7 | R5: 7.8 | S5: -++--
A6: TempMultiOde_SimGait_MB_3 | B6: 0.93 | C6: 1.28 | D6: 28.6 | E6: 118 | G6: 38 | J6: 106 | K6: 93 | L6: y | M6: y | N6: y | O6: y | P6: zano boland | Q6: 15.4 | R6: 5.6 | S6: ++---
A7: TempMultiOde_SimGait_MB_4 | B7: 0.64 | C7: 1.25 | D7: 4.1 | E7: 68 | G7: 16 | J7: 100 | K7: 48 | L7: y | M7: y | N7: y | O7: y | P7: zano kham | Q7: 12.8 | R7: 7.2 | S7: -++--
A8: TempMultiOde_SimGait_MB_5 | B8: 0.65 | C8: 1.29 | D8: 5.8 | E8: 74 | G8: 21 | J8: 89 | K8: 49 | L8: y | M8: y | N8: y | O8: y | P8: kamar bazi dare | Q8: 12.5 | R8: 61 | S8: -++--
A9: TempMultiOde_SimGait_MB_6 | B9: 0.9 | C9: 1.1 | D9: 3.6 | E9: 25.33 | F9: 21.01 | G9: 6.53 | H9: 16.46 | I9: 7.15 | J9: 87 | K9: 60 | L9: y | M9: y | N9: y | O9: y | P9: good | Q9: 12.1 | R9: 7.2 | S9: +++-- | T9: 0.855
A10: TempMultiOde_SimGait_MB_7 | B10: 0.46 | C10: 1.25 | D10: 5 | E10: 49 | G10: 20 | J10: 86 | K10: 63 | L10: y | M10: y | N10: y | O10: y | P10: good | Q10: 11 | R10: 5 | S10: -++--
A11: TempMultiOde_SimGait_MB_8 | B11: 0.97 | C11: 1.08 | D11: 3.2 | E11: 33 | G11: 10 | J11: 59 | K11: 59 | L11: y | M11: y | N11: y | O11: y | P11: good | Q11: 11.5 | R11: 6.9 | S11: +++--
A12: TempMultiOde_SimGait_MB_9 | B12: 0.7 | C12: 1.13 | D12: 3.3 | E12: 89 | G12: 44 | J12: 74 | K12: 56 | L12: y | M12: y | N12: y | O12: y | P12: zano kam | Q12: 13.4 | R12: 3 | S12: +++--
A13: TempMultiOde_SimGait_MB_10 | B13: 0.88 | C13: 1.1 | D13: 13.2 | E13: 55 | G13: 23 | J13: 50 | K13: 55 | L13: y | M13: y | N13: y | O13: y | P13: zano boland | Q13: 12 | R13: 5.9 | S13: +++--
A14: TempMultiOde_SimGait_MB_11 | B14: 0.35 | C14: 1.23 | D14: 4.52 | E14: 67 | G14: 18 | J14: 199 | K14: 150 | L14: y | M14: y | N14: y | O14: y | P14: good | Q14: 11.1 | R14: 12.3 | S14: -+--+
A15: TempMultiOde_SimGait_MB_12 | B15: 0.7 | C15: 1.14 | D15: 8.6 | E15: 40 | G15: 11 | J15: 67 | K15: 42 | L15: y | M15: y | N15: y | O15: y | P15: good | Q15: 11.9 | R15: 7.3 | S15: +++--
A16: TempMultiOde_SimGait_MB_13 | B16: 0.64 | C16: 1.19 | D16: 4 | E16: 64 | G16: 33 | J16: 132 | K16: 165 | L16: y | M16: y | N16: y | O16: y | P16: good | Q16: 12.59 | R16: 5.5 | S16: ++---
A17: TempMultiOde_SimGait_MB_14 | B17: 0.84 | C17: 1.1 | D17: 2.5 | E17: 65 | G17: 20 | J17: 87 | K17: 51 | L17: y | M17: y | N17: y | O17: y | P17: kamar bazi dare | Q17: 11.5 | R17: 4.9 | S17: ++---
A18: TempMultiOde_SimGait_MB_15 | B18: 0.92 | C18: 1.31 | D18: 9.5 | E18: 118 | G18: 85 | J18: 140 | K18: 76 | L18: y | M18: y | N18: y | O18: y? | P18: zano bala | Q18: 10.9 | R18: 4.8 | S18: +++--
A19: TempMultiOde_SimGait_MB_16 | B19: 0.79 | C19: 1.14 | D19: 7.9 | E19: 59 | G19: 16 | J19: 69 | K19: 74 | L19: y | M19: y | N19: y | O19: y | P19: zano bala | Q19: 10.7 | R19: 11.8 | S19: ++---
A20: TempMultiOde_SimGait_MB_17 | B20: 1.71 | C20: '----- | D20: '----- | E20: '----- | F20: '----- | G20: '----- | H20: '----- | I20: '----- | J20: '----- | K20: '----- | L20: n | M20: ----- | N20: '----- | O20: '----- | S20: +++--
A21: TempMultiOde_SimGait_MB_18 | B21: 0.65 | C21: 1.15 | D21: 3.11 | E21: 39 | G21: 8.9 | J21: 85 | K21: 71 | L21: y | M21: y | N21: y | O21: y | P21: good | Q21: 11.5 | R21: 6.19 | S21: -++--
A22: TempMultiOde_SimGait_MB_19 | B22: 0.87 | C22: 1.16 | D22: 2.8 | E22: 35 | G22: 15 | J22: 56 | K22: 42 | L22: y | M22: y | N22: y | O22: y | P22: good | Q22: 11.5 | R22: 6.4 | S22: ++---
A23: TempMultiOde_SimGait_MB_20 | B23: 1.4 | C23: 0.62 | D23: 2.7 | E23: 18 | G23: 7.7 | J23: 71 | K23: 59 | L23: y | M23: y | N23: y | O23: y | P23: ro be kond | Q23: 13.5 | R23: 6.3 | S23: -+---
D25: min | G25: =MIN(G4:G23) -> 6.53
A30: =A9 -> TempMultiOde_SimGait_MB_6 | B30: =B9 -> 0.9 | C30: =C9 -> 1.1 | D30: =D9 -> 3.6 | E30: =E9 -> 25.33 | F30: =F9 -> 21.01 | G30: =G9 -> 6.53 | H30: =H9 -> 16.46 | ... T30: =T9 -> 0.855

Sheet SimGait_MD
A1: State: | C1: Cost func. consists one 10 step, full constraint/punishment on mechanical unstability
A2: Name | B2: speed | D2: foot height | E2: Req. Work | F2: Act. Work | J2: max u | L2: gait stability | M2: mech. Stabiity | P2: gait Type | Q2: angle1 | R2: angle2 | S2: speed sign | T2: delta
B3: 1 Steps | C3: 10 Steps | F3: M | G3: MB | H3: MD | I3: MBD | J3: Req. | K3: Act (MB) | M3: Aft. Imp. | N3: Dur. Walk | O3: At Imp.
A4: TempMultiOde_SimGait_MD_1 | B4: 0.96 | L4: n
A5: TempMultiOde_SimGait_MD_2 | B5: 1.06 | C5: 1.006 | D5: 3.4 | E5: 28 | H5: 19 | J5: 109 | K5: 71 | L5: y | M5: y | N5: y | O5: y | P5: zano kamel saf mishavad | Q5: 12.9 | R5: 6.1 | S5: ++---
A6: TempMultiOde_SimGait_MD_3 | B6: 1.22 | C6: 1.11 | D6: 14.3 | E6: 97 | H6: 74 | J6: 147 | K6: 119 | L6: y | M6: y | N6: y | O6: semi y | P6: zano kheili kham mishavad | Q6: 15.44 | R6: 22.9 | S6: ++---
A7: TempMultiOde_SimGait_MD_4 | B7: 0.58 | C7: 1.17 | D7: 4.5 | E7: 57 | H7: 39 | J7: 79 | K7: 84 | L7: y | M7: y | N7: y | O7: y | P7: good | Q7: 12.55 | R7: 5.68 | S7: ++---
A8: TempMultiOde_SimGait_MD_5 | B8: 0.87 | C8: 1.21 | D8: 1.69 | E8: 33 | H8: 18 | J8: 86 | K8: 79 | L8: y | M8: y | N8: y | O8: y | P8: roye zamin mikeshad | Q8: 11.7 | R8: 4.6 | S8: -+---
A9: TempMultiOde_SimGait_MD_6 | B9: 0.71 | C9: 1.22 | D9: 3.7 | E9: 40 | H9: 29 | J9: 88.2 | K9: 81.4 | L9: y | M9: y | N9: y | O9: y | P9: good | Q9: 12.4 | R9: 5 | S9: -++--
A10: TempMultiOde_SimGait_MD_7 | B10: 0.73 | C10: 1.14 | D10: 3.2 | E10: 26.9 | H10: 17 | J10: 121 | K10: 95 | L10: y | M10: y | N10: y | O10: n | P10: good | Q10: 11.9 | R10: 6.8 | S10: ++---
A11: TempMultiOde_SimGait_MD_8 | B11: 1.01 | C11: 0.99 | D11: 12.6 | E11: 47 | H11: 38 | J11: 73 | K11: 62 | L11: y | M11: y | N11: y | O11: y | P11: pa boland | Q11: 13.9 | R11: 5.9 | S11: -++--
A12: TempMultiOde_SimGait_MD_9 | B12: 1.06 | C12: 0.94 | D12: 23 | E12: 138 | H12: 121 | J12: 105 | K12: 85 | L12: y | M12: y | N12: y | O12: y | P12: pa boland | Q12: 14 | R12: 2.23 | S12: ++++-
A13: TempMultiOde_SimGait_MD_10 | B13: 1.06 | C13: 1.13 | D13: 2.6 | E13: 32.6 | F13: 22.36 | G13: 9.87 | H13: 16.96 | I13: 9.92 | J13: 72 | K13: 39 | L13: y | M13: y | N13: y | O13: y | P13: good | Q13: 12.3 | R13: 5 | S13: +++-- | T13: 0.882
A14: TempMultiOde_SimGait_MD_11 | B14: 0.56 | C14: 1.21 | D14: 2.6 | E14: 42 | H14: 26 | J14: 86 | K14: 77 | L14: y | M14: y | N14: y | O14: y | P14: kamar bazi darad | Q14: 8.1 | R14: 2.6 | S14: ++---
A15: TempMultiOde_SimGait_MD_12 | B15: 1.27 | C15: 0.95 | D15: 6.26 | E15: 39 | H15: 30 | J15: 85 | K15: 92 | L15: y | M15: y | N15: y | O15: y | P15: lagan bala payeen mishe | Q15: 15.4 | R15: 12.6 | S15: ++---
A16: TempMultiOde_SimGait_MD_13 | B16: 1.11 | C16: 0.94 | D16: 2.9 | E16: 22 | H16: 14 | J16: 40 | K16: 30 | L16: y | M16: y | N16: y | O16: y | P16: good | Q16: 12.3 | R16: 7.4 | S16: +++--
A17: TempMultiOde_SimGait_MD_14 | B17: 1.01 | C17: 0.99 | D17: 5.2 | E17: 25 | H17: 17 | J17: 33 | K17: 25 | L17: y | M17: y | N17: y | O17: y | P17: not so good | Q17: 12.5 | R17: 6.8 | S17: +++--
A18: TempMultiOde_SimGait_MD_15 | B18: 0.95 | C18: 1.13 | D18: 5.4 | E18: 54 | H18: 41 | J18: 116 | K18: 135 | L18: y | M18: y | N18: y | O18: y | P18: good | Q18: 13.5 | R18: 4.7 | S18: ++---
A19: TempMultiOde_SimGait_MD_16 | B19: 1.03 | C19: 1 | D19: 8.4 | E19: 28 | H19: 24 | J19: 138 | K19: 109 | L19: y | M19: y | N19: y | O19: y | P19: good | Q19: 13.2 | R19: 7.2 | S19: ++---
A20: TempMultiOde_SimGait_MD_17 | B20: -- | C20: -- | D20: -- | E20: -- | H20: -- | J20: -- | K20: -- | L20: n | M20: n | N20: n | O20: n
A21: TempMultiOde_SimGait_MD_18 | B21: 0.43 | C21: 1.12 | D21: 7.45 | E21: 104 | H21: 78 | J21: 140 | K21: 76 | L21: y | M21: y | N21: y | O21: y | P21: not so good | Q21: 10.6 | R21: 4.7 | S21: +++--
A22: TempMultiOde_SimGait_MD_19 | B22: 0.95 | C22: 1.02 | D22: 3.3 | E22: 33 | H22: 16 | J22: 80 | K22: 60 | L22: y | M22: y | N22: y | O22: y | P22: engar nok pa mire | Q22: 12.8 | R22: 6.1 | S22: +++--
A23: TempMultiOde_SimGait_MD_20 | B23: 0.39 | C23: 1.2 | D23: 7.55 | E23: 54 | H23: 36 | J23: 99 | K23: 94 | L23: y | M23: y | N23: y | O23: y | P23: yavash bw tond | Q23: 10.9 | R23: 6.1 | S23: +++--
D25: min | H25: =MIN(H4:H23) -> 14
A30: =A13 -> TempMultiOde_SimGait_MD_10 | B30: =B13 -> 1.06 | C30: =C13 -> 1.13 | D30: =D13 -> 2.6 | E30: =E13 -> 32.6 | F30: =F13 -> 22.36 | G30: =G13 -> 9.87 | H30: =H13 -> 16.96 | ... T30: =T13 -> 0.882

Sheet SimGait_MBD
A1: State: | C1: Cost func. consists one 10 step, full constraint/punishment on mechanical unstability
A2: Name | B2: speed | D2: foot height | E2: Req. Work | F2: Act. Work | J2: max u | L2: gait stability | M2: mech. Stabiity | P2: gait Type | Q2: angle1 | R2: angle2 | S2: speed sign | T2: delta
B3: 1 Steps | C3: 10 Steps | F3: M | G3: MB | H3: MD | I3: MBD | J3: Req. | K3: Act (MB) | M3: Aft. Imp. | N3: Dur. Walk | O3: At Imp.
A4: TempMultiOde_SimGait_MBD_1 | B4: 0.89 | C4: 1.11 | D4: 4 | E4: 41 | I4: 8.9 | J4: 84 | K4: 79 | L4: y | M4: y | N4: y | O4: y | P4: good | Q4: 13.1 | R4: 6.4 | S4: +++--
A5: TempMultiOde_SimGait_MBD_2 | B5: 0.8 | C5: 1.13 | D5: 8.5 | E5: 56 | I5: 20 | J5: 111 | K5: 73 | L5: y | M5: y | N5: y | O5: y | P5: good | Q5: 12.9 | R5: 6.6 | S5: ++---
A6: TempMultiOde_SimGait_MBD_3 | B6: 1.24 | C6: 0.89 | D6: 3.2 | E6: 24 | I6: 14 | J6: 52 | K6: 57 | L6: y | M6: y | N6: y | O6: y | P6: good | Q6: 14 | R6: 7.3 | S6: +++--
A7: TempMultiOde_SimGait_MBD_4 | B7: 1.26 | C7: 1.15 | D7: 3.7 | E7: 43 | I7: 15 | J7: 67 | K7: 28 | L7: y | M7: y | N7: y | O7: y | P7: good | Q7: 13.4 | R7: 6 | S7: ++---
A8: TempMultiOde_SimGait_MBD_5 | B8: 1.14 | C8: 0.75 | D8: 14 | E8: 67 | I8: 62 | J8: 123 | K8: 87 | L8: y | M8: y | N8: y | O8: y | P8: pa boland | Q8: 12.3 | R8: 6.4 | S8: ++++-
A9: TempMultiOde_SimGait_MBD_6 | B9: 1.2 | C9: 1.13 | D9: 4.3 | E9: 46 | I9: 8.5 | J9: 60 | K9: 45 | L9: y | M9: y | N9: y | O9: y | P9: kamar bazi mikonad | Q9: 13.9 | R9: 8.6 | S9: ++---
A10: TempMultiOde_SimGait_MBD_7 | B10: 0.44 | C10: 1.6 | D10: 15.7 | E10: 323 | I10: 226 | J10: 269 | K10: 220 | L10: y | M10: y | N10: y | O10: y | P10: pa boland | Q10: 10.7 | R10: 7 | S10: ++-+-
A11: TempMultiOde_SimGait_MBD_8 | B11: 0.64 | C11: 1.23 | D11: 4.6 | E11: 45 | I11: 23 | J11: 67 | K11: 61 | L11: y | M11: y | N11: y | O11: y | P11: not so good | Q11: 13.7 | R11: 5.2 | S11: +++--
A12: TempMultiOde_SimGait_MBD_9 | B12: -- | C12: -- | D12: -- | E12: -- | I12: -- | J12: -- | K12: -- | L12: n | M12: -- | N12: -- | O12: -- | P12: -- | Q12: -- | R12: -- | S12: --
A13: TempMultiOde_SimGait_MBD_10 | B13: 0.92 | C13: 1.11 | D13: 2.7 | E13: 26 | F13: 16.68 | G13: 4.46 | H13: 13.71 | I13: 5.12 | J13: 57 | K13: 41 | L13: y | M13: y | N13: y | O13: y | P13: good | Q13: 12.7 | R13: 5.22 | S13: -++-- | T13: 0.879
A14: TempMultiOde_SimGait_MBD_11 | B14: 0.81 | C14: 1.12 | D14: 4.5 | E14: 59 | I14: 42 | J14: 120 | K14: 100 | L14: y | M14: y | N14: y | O14: y | P14: zano boland | Q14: 12.6 | R14: 6.3 | S14: +++--
A15: TempMultiOde_SimGait_MBD_12 | B15: 1.3 | C15: 0.7 | D15: 8 | E15: 110 | I15: 99 | J15: 122 | K15: 116 | L15: y | M15: n | N15: n | O15: y | P15: ba naz rah mire | Q15: 10.8 | R15: 7.3 | S15: ++---
A16: TempMultiOde_SimGait_MBD_13 | B16: 1.22 | C16: 0.89 | D16: 3.7 | E16: 33 | I16: 16 | J16: 50 | K16: 51 | L16: y | M16: y | N16: y | O16: y | P16: zano saf mishe | Q16: 12.3 | R16: 5.3 | S16: -++--
A17: TempMultiOde_SimGait_MBD_14 | B17: 0.8 | C17: 1.29 | D17: 3.8 | E17: 39 | I17: 12 | J17: 57 | K17: 41 | L17: y | M17: y | N17: y | O17: y | P17: good | Q17: 12.5 | R17: 5.8 | S17: +++--
A18: TempMultiOde_SimGait_MBD_15 | B18: 1.06 | C18: 1.01 | D18: 4.11 | E18: 116 | I18: 24 | J18: 116 | K18: 115 | L18: y | M18: y | N18: y | O18: y | P18: kamar bazi mikonad | Q18: 12.1 | R18: 10.2 | S18: +++--
A19: TempMultiOde_SimGait_MBD_16 | B19: 0.89 | C19: 1.3 | D19: 7.4 | E19: 61 | I19: 21 | J19: 81 | K19: 68 | L19: y | M19: y | N19: y | O19: y | P19: good | Q19: 12.7 | R19: 6.4 | S19: ++---
A20: TempMultiOde_SimGait_MBD_17 | B20: 0.53 | C20: 1.3 | D20: 31 | E20: 577 | I20: 404 | J20: 260 | K20: 242 | L20: y | M20: y | N20: y | O20: y | P20: zano boland | Q20: 12.2 | R20: 2.14 | S20: ++++-
A21: TempMultiOde_SimGait_MBD_18 | B21: 1.08 | C21: 1.08 | D21: 4.8 | E21: 42 | I21: 14 | J21: 91 | K21: 103 | L21: y | M21: y | N21: y | O21: y | P21: good | Q21: 11.9 | R21: 2.7 | S21: -++--
A22: TempMultiOde_SimGait_MBD_19 | B22: -- | C22: -- | D22: -- | E22: -- | I22: -- | J22: -- | K22: -- | L22: n | M22: -- | N22: -- | O22: -- | P22: -- | Q22: -- | R22: -- | S22: --
A23: TempMultiOde_SimGait_MBD_20 | B23: 1.002 | C23: 1.27 | D23: 4.5 | E23: 48 | I23: 14 | J23: 70 | K23: 64 | P23: good | Q23: 13.8 | R23: 7.5 | S23: +++--
D25: min | I25: =MIN(I4:I23) -> 5.12
A30: =A13 -> TempMultiOde_SimGait_MBD_10 | B30: =B13 -> 0.92 | C30: =C13 -> 1.11 | D30: =D13 -> 2.7 | E30: =E13 -> 26 | F30: =F13 -> 16.68 | G30: =G13 -> 4.46 | H30: =H13 -> 13.71 | ... T30: =T13 -> 0.879

Sheet Compare
B1: Name | C1: speed | E1: foot height | F1: Req. Work | G1: Act. Work | K1: max u | M1: gait stability | N1: mech. Stabiity | Q1: gait Type | R1: angle1 | S1: angle2 | T1: speed sign | U1: delta
C2: 1 Steps | D2: 10 Steps | G2: M | H2: MB | I2: MD | J2: MBD | K2: Req. | L2: Act (MB) | N2: Aft. Imp. | O2: Dur. Walk | P2: At Imp.
B3: Initial | C3: 1.77 | D3: 1.75 | E3: 1.27 | F3: 51.57 | G3: 30.65 | H3: 14.55 | I3: 23.09 | J3: 14.57 | K3: 233.52 | L3: --- | M3: y | N3: n | O3: y | P3: y | Q3: good | R3: 11 | S3: 6 | T3: ++---
F4: 3046.5 | G4: 639.17 | H4: 131.7 | I4: 346.68 | J4: 131.46
A5: Gait | B5: =Gait!A30 -> TempMultiOde_Gait_8 | C5: =Gait!B30 -> 0.79 | D5: =Gait!C30 -> 1.09 | E5: =Gait!D30 -> 3.33 | F5: =Gait!E30 -> 19 | G5: 13.9 | H5: =Gait!G30 -> 12.53 | I5: =Gait!H30 -> 13.44 | J5: =Gait!I30 -> 12.44 | K5: =Gait!J30 -> 63 | L5: --- | M5: =Gait!L30 -> y | N5: =Gait!M30 -> y | O5: =Gait!N30 -> y | P5: =Gait!O30 -> y | Q5: =Gait!P30 -> roy zamin mikeshad | R5: =Gait!Q30 -> 12.4 | S5: =Gait!R30 -> 5.7 | T5: =Gait!S30 -> ++--- | U5: =Gait!T30 -> 0.8521
E6: cost | F6: 344.92 | G6: 122.13 | H6: 91.7 | I6: 121.09 | J6: 91.58
A7: SimGait_M | B7: =SimGait_M!A35 -> TempMultiOde_SimGait_M_12 | C7: =SimGait_M!B35 -> 0.96 | D7: =SimGait_M!C35 -> 1.01 | E7: =SimGait_M!D35 -> 6.2 | F7: =SimGait_M!E35 -> 27.52 | G7: =SimGait_M!F35 -> 20.49 | H7: =SimGait_M!G35 -> 13.92 | I7: =SimGait_M!H35 -> 18.77 | ... U7: =SimGait_M!T35 -> 0.785
F8: 286.63 | G8: 115.21 | H8: 74.88 | I8: 106.3 | J8: 117.22
A9: SimGait_MB | B9: =SimGait_MB!A30 -> TempMultiOde_SimGait_MB_6 | C9: =SimGait_MB!B30 -> 0.9 | D9: =SimGait_MB!C30 -> 1.1 | E9: =SimGait_MB!D30 -> 3.6 | F9: =SimGait_MB!E30 -> 25.33 | G9: =SimGait_MB!F30 -> 21.01 | H9: =SimGait_MB!G30 -> 6.53 | I9: =SimGait_MB!H30 -> 16.46 | ... U9: =SimGait_MB!T30 -> 0.855
F10: 393.65 | G10: 174.76 | H10: 38.61 | I10: 136.91 | J10: 47.58
A11: SimGait_MD | B11: =SimGait_MD!A30 -> TempMultiOde_SimGait_MD_10 | C11: =SimGait_MD!B30 -> 1.06 | D11: =SimGait_MD!C30 -> 1.13 | E11: =SimGait_MD!D30 -> 2.6 | F11: =SimGait_MD!E30 -> 32.6 | G11: =SimGait_MD!F30 -> 22.36 | H11: =SimGait_MD!G30 -> 9.87 | I11: =SimGait_MD!H30 -> 16.96 | ... U11: =SimGait_MD!T30 -> 0.882
F12: 702.8 | G12: 157.45 | H12: 56.59 | I12: 125.72 | J12: 57.97
A13: SimGait_MBD | B13: =SimGait_MBD!A30 -> TempMultiOde_SimGait_MBD_10 | C13: =SimGait_MBD!B30 -> 0.92 | D13: =SimGait_MBD!C30 -> 1.11 | E13: =SimGait_MBD!D30 -> 2.7 | F13: =SimGait_MBD!E30 -> 26 | G13: =SimGait_MBD!F30 -> 16.68 | H13: =SimGait_MBD!G30 -> 4.46 | I13: =SimGait_MBD!H30 -> 13.71 | ... U13: =SimGait_MBD!T30 -> 0.879
F14: 519.16 | G14: 155.76 | H14: 16.32 | I14: 119.67 | J14: 20.51
